<?xml version="1.0" encoding="UTF-8"?>
<!-- Generated by org.testng.reporters.JUnitXMLReporter -->
<testsuite hostname="dhqianli" name="d8c6d48b7d63" tests="1" failures="1" timestamp="22 Oct 2017 05:13:03 GMT" time="33.953" errors="0">
  <testcase name="testTestSuite" time="11.605" classname="cn.crazy.appium.keyworddriver.TestSuiteByExcel">
    <failure type="java.lang.AssertionError" message="执行出现异常，测试用例执行失败！">
      <![CDATA[java.lang.AssertionError: 执行出现异常，测试用例执行失败！
	at cn.crazy.appium.keyworddriver.TestSuiteByExcel.testTestSuite(TestSuiteByExcel.java:88)
	at java.util.concurrent.FutureTask.run(FutureTask.java:262)
	at java.util.concurrent.ThreadPoolExecutor.runWorker(ThreadPoolExecutor.java:1145)
	at java.util.concurrent.ThreadPoolExecutor$Worker.run(ThreadPoolExecutor.java:615)
	at java.lang.Thread.run(Thread.java:744)
... Removed 17 stack frames]]>
    </failure>
  </testcase> <!-- testTestSuite -->
</testsuite> <!-- d8c6d48b7d63 -->
