<?xml version="1.0" encoding="UTF-8"?>
<testsuite name="d8c6d48b7d63"
           tests="1"
           failures="1"
           errors="0"
           skipped="0"
           time="11.605">
  <properties />
            <testcase name="testTestSuite" time="11.605" classname="cn.crazy.appium.keyworddriver.TestSuiteByExcel">
                <failure type="java.lang.AssertionError"
                  message="执行出现异常，测试用例执行失败！"
              >
<![CDATA[java.lang.AssertionError: 执行出现异常，测试用例执行失败！
  org.testng.Assert.fail(Assert.java:94)
  cn.crazy.appium.keyworddriver.TestSuiteByExcel.testTestSuite(TestSuiteByExcel.java:88)
  sun.reflect.NativeMethodAccessorImpl.invoke0(Native Method)
  sun.reflect.NativeMethodAccessorImpl.invoke(NativeMethodAccessorImpl.java:57)
  sun.reflect.DelegatingMethodAccessorImpl.invoke(DelegatingMethodAccessorImpl.java:43)
  java.lang.reflect.Method.invoke(Method.java:606)
  org.testng.internal.MethodInvocationHelper.invokeMethod(MethodInvocationHelper.java:86)
  org.testng.internal.Invoker.invokeMethod(Invoker.java:643)
  org.testng.internal.Invoker.invokeTestMethod(Invoker.java:820)
  org.testng.internal.Invoker.invokeTestMethods(Invoker.java:1128)
  org.testng.internal.TestMethodWorker.invokeTestMethods(TestMethodWorker.java:129)
  org.testng.internal.TestMethodWorker.run(TestMethodWorker.java:112)
  org.testng.TestRunner.privateRun(TestRunner.java:782)
  org.testng.TestRunner.run(TestRunner.java:632)
  org.testng.SuiteRunner.runTest(SuiteRunner.java:366)
  org.testng.SuiteRunner.access$000(SuiteRunner.java:39)
  org.testng.SuiteRunner$SuiteWorker.run(SuiteRunner.java:400)
  org.testng.internal.thread.ThreadUtil$2.call(ThreadUtil.java:64)
  java.util.concurrent.FutureTask.run(FutureTask.java:262)
  java.util.concurrent.ThreadPoolExecutor.runWorker(ThreadPoolExecutor.java:1145)
  java.util.concurrent.ThreadPoolExecutor$Worker.run(ThreadPoolExecutor.java:615)
  java.lang.Thread.run(Thread.java:744)
]]>
      </failure>

          </testcase>
  
  
  
</testsuite>
