<?xml version="1.0" encoding="UTF-8"?>
<!-- Generated by org.testng.reporters.JUnitReportReporter -->
<testsuite hostname="dhqianli" name="cn.crazy.appium.keyworddriver.TestSuiteByExcel" tests="1" failures="1" timestamp="22 Oct 2017 05:13:04 GMT" time="11.605" errors="0">
  <testcase name="testTestSuite" time="11.605" classname="cn.crazy.appium.keyworddriver.TestSuiteByExcel">
    <failure type="java.lang.AssertionError" message="执行出现异常，测试用例执行失败！">
      <![CDATA[java.lang.AssertionError: 执行出现异常，测试用例执行失败！
	at org.testng.Assert.fail(Assert.java:94)
	at cn.crazy.appium.keyworddriver.TestSuiteByExcel.testTestSuite(TestSuiteByExcel.java:88)
	at sun.reflect.NativeMethodAccessorImpl.invoke0(Native Method)
	at sun.reflect.NativeMethodAccessorImpl.invoke(NativeMethodAccessorImpl.java:57)
	at sun.reflect.DelegatingMethodAccessorImpl.invoke(DelegatingMethodAccessorImpl.java:43)
	at java.lang.reflect.Method.invoke(Method.java:606)
	at org.testng.internal.MethodInvocationHelper.invokeMethod(MethodInvocationHelper.java:86)
	at org.testng.internal.Invoker.invokeMethod(Invoker.java:643)
	at org.testng.internal.Invoker.invokeTestMethod(Invoker.java:820)
	at org.testng.internal.Invoker.invokeTestMethods(Invoker.java:1128)
	at org.testng.internal.TestMethodWorker.invokeTestMethods(TestMethodWorker.java:129)
	at org.testng.internal.TestMethodWorker.run(TestMethodWorker.java:112)
	at org.testng.TestRunner.privateRun(TestRunner.java:782)
	at org.testng.TestRunner.run(TestRunner.java:632)
	at org.testng.SuiteRunner.runTest(SuiteRunner.java:366)
	at org.testng.SuiteRunner.access$000(SuiteRunner.java:39)
	at org.testng.SuiteRunner$SuiteWorker.run(SuiteRunner.java:400)
	at org.testng.internal.thread.ThreadUtil$2.call(ThreadUtil.java:64)
	at java.util.concurrent.FutureTask.run(FutureTask.java:262)
	at java.util.concurrent.ThreadPoolExecutor.runWorker(ThreadPoolExecutor.java:1145)
	at java.util.concurrent.ThreadPoolExecutor$Worker.run(ThreadPoolExecutor.java:615)
	at java.lang.Thread.run(Thread.java:744)
]]>
    </failure>
  </testcase> <!-- testTestSuite -->
</testsuite> <!-- cn.crazy.appium.keyworddriver.TestSuiteByExcel -->
